<?xml version="1.0" ?>
<!-- =================================================================================== -->
<!-- |    This document was autogenerated by xacro from src/xxx_gazebo/robot/xxx.xacro | -->
<!-- |    EDITING THIS FILE BY HAND IS NOT RECOMMENDED                                 | -->
<!-- =================================================================================== -->
<robot name="xxx">
  <!-- Read in the yaml dict as mp (short for model parameters) -->
  <!-- Read in the yaml dict as mp (short for model parameters) -->
  <link name="base_link">
    <visual>
      <origin rpy="0.0 0.0 1.5707963267948966" xyz="0.0 0.0 -0.018"/>
      <geometry>
        <mesh filename="/home/pi31415/xxx2_ws/install/xxx_description/share/xxx_description/meshes/coconut.stl"/>
      </geometry>
      <material name="chassis_color">
        <color rgba="1 1 1 1"/>
      </material>
    </visual>
    <inertial>
      <origin xyz="0.0002 0.0001 -0.0001"/>
      <mass value="40.0"/>
      <inertia ixx="1.79366667" ixy="0" ixz="0" iyy="1.28666667" iyz="0" izz="0.230966667"/>
    </inertial>
    <collision>
      <geometry>
        <box size="0.65 0.55 0.25"/>
      </geometry>
    </collision>
  </link>
  <link name="base_footprint"/>
  <joint name="base_offset" type="fixed">
    <parent link="base_footprint"/>
    <child link="base_link"/>
    <origin xyz="0.0 0.0 0.165"/>
  </joint>
  <link name="left_wheel">
    <visual>
      <origin rpy="0.0 0.0 0.0" xyz="0.0 0.0 0.0"/>
      <geometry>
        <cylinder length="0.04" radius="0.08"/>
      </geometry>
      <material name="left_wheel_color">
        <color rgba="0 0 0 1"/>
      </material>
    </visual>
    <inertial>
      <origin xyz="0 0 0"/>
      <mass value="2.9"/>
      <inertia ixx="0.00564437" ixy="0" ixz="0" iyy="0.00564437" iyz="0" izz="0.01047625"/>
    </inertial>
    <collision>
      <geometry>
        <cylinder length="0.04" radius="0.08"/>
      </geometry>
      <surface>
        <friction>
          <ode>
            <mu>1000</mu>
            <mu2>1000</mu2>
          </ode>
        </friction>
      </surface>
    </collision>
  </link>
  <joint name="left_wheel_joint" type="continuous">
    <origin rpy="-1.5707963267948966 0.0 0.0" xyz="0.0 0.225 -0.085"/>
    <parent link="base_link"/>
    <child link="left_wheel"/>
    <axis xyz="0.0 0.0 1.0"/>
    <joint_properties damping="1.0" friction="1.0"/>
  </joint>
  <link name="right_wheel">
    <visual>
      <origin rpy="0.0 0.0 0.0" xyz="0.0 0.0 0.0"/>
      <geometry>
        <cylinder length="0.04" radius="0.08"/>
      </geometry>
      <material name="right_wheel_color">
        <color rgba="0 0 0 1"/>
      </material>
    </visual>
    <inertial>
      <origin xyz="0 0 0"/>
      <mass value="2.9"/>
      <inertia ixx="0.00564437" ixy="0" ixz="0" iyy="0.00564437" iyz="0" izz="0.01047625"/>
    </inertial>
    <collision>
      <geometry>
        <cylinder length="0.04" radius="0.08"/>
      </geometry>
      <surface>
        <friction>
          <ode>
            <mu>1000</mu>
            <mu2>1000</mu2>
          </ode>
        </friction>
      </surface>
    </collision>
  </link>
  <joint name="right_wheel_joint" type="continuous">
    <origin rpy="-1.5707963267948966 0.0 0.0" xyz="0.0 -0.225 -0.085"/>
    <parent link="base_link"/>
    <child link="right_wheel"/>
    <axis xyz="0.0 0.0 1.0"/>
    <joint_properties damping="1.0" friction="1.0"/>
  </joint>
  <link name="left_front_castor">
    <visual>
      <geometry>
        <cylinder length="0.02" radius="0.035"/>
      </geometry>
      <material name="left_front_castor_color">
        <color rgba="0.5 0.5 0 1"/>
      </material>
    </visual>
    <inertial>
      <origin xyz="0 0 0"/>
      <mass value="0.2"/>
      <inertia ixx="4.437e-05" ixy="0" ixz="0" iyy="4.437e-05" iyz="0" izz="0.00047625"/>
    </inertial>
    <collision>
      <geometry>
        <cylinder length="0.02" radius="0.035"/>
      </geometry>
      <surface>
        <friction>
          <ode>
            <mu>0</mu>
            <mu2>0</mu2>
          </ode>
        </friction>
      </surface>
    </collision>
  </link>
  <joint name="left_front_castor_joint" type="continuous">
    <origin rpy="-1.5707963267948966 0 0" xyz="           0.23            0.16            -0.12990000000000002         "/>
    <parent link="base_link"/>
    <child link="left_front_castor"/>
    <axis xyz="0.0 0.0 1.0"/>
  </joint>
  <link name="right_front_castor">
    <visual>
      <geometry>
        <cylinder length="0.02" radius="0.035"/>
      </geometry>
      <material name="right_front_castor_color">
        <color rgba="0.5 0.5 0 1"/>
      </material>
    </visual>
    <inertial>
      <origin xyz="0 0 0"/>
      <mass value="0.2"/>
      <inertia ixx="4.437e-05" ixy="0" ixz="0" iyy="4.437e-05" iyz="0" izz="0.00047625"/>
    </inertial>
    <collision>
      <geometry>
        <cylinder length="0.02" radius="0.035"/>
      </geometry>
      <surface>
        <friction>
          <ode>
            <mu>0</mu>
            <mu2>0</mu2>
          </ode>
        </friction>
      </surface>
    </collision>
  </link>
  <joint name="right_front_castor_joint" type="continuous">
    <origin rpy="-1.5707963267948966 0 0" xyz="           -0.23            0.16            -0.12990000000000002         "/>
    <parent link="base_link"/>
    <child link="right_front_castor"/>
    <axis xyz="0.0 0.0 1.0"/>
  </joint>
  <link name="left_rear_castor">
    <visual>
      <geometry>
        <cylinder length="0.02" radius="0.035"/>
      </geometry>
      <material name="left_rear_castor_color">
        <color rgba="0.5 0.5 0 1"/>
      </material>
    </visual>
    <inertial>
      <origin xyz="0 0 0"/>
      <mass value="0.2"/>
      <inertia ixx="4.437e-05" ixy="0" ixz="0" iyy="4.437e-05" iyz="0" izz="0.00047625"/>
    </inertial>
    <collision>
      <geometry>
        <cylinder length="0.02" radius="0.035"/>
      </geometry>
      <surface>
        <friction>
          <ode>
            <mu>0</mu>
            <mu2>0</mu2>
          </ode>
        </friction>
      </surface>
    </collision>
  </link>
  <joint name="left_rear_castor_joint" type="continuous">
    <origin rpy="-1.5707963267948966 0 0" xyz="           0.23            -0.16            -0.12990000000000002         "/>
    <parent link="base_link"/>
    <child link="left_rear_castor"/>
    <axis xyz="0.0 0.0 1.0"/>
  </joint>
  <link name="right_rear_castor">
    <visual>
      <geometry>
        <cylinder length="0.02" radius="0.035"/>
      </geometry>
      <material name="right_rear_castor_color">
        <color rgba="0.5 0.5 0 1"/>
      </material>
    </visual>
    <inertial>
      <origin xyz="0 0 0"/>
      <mass value="0.2"/>
      <inertia ixx="4.437e-05" ixy="0" ixz="0" iyy="4.437e-05" iyz="0" izz="0.00047625"/>
    </inertial>
    <collision>
      <geometry>
        <cylinder length="0.02" radius="0.035"/>
      </geometry>
      <surface>
        <friction>
          <ode>
            <mu>0</mu>
            <mu2>0</mu2>
          </ode>
        </friction>
      </surface>
    </collision>
  </link>
  <joint name="right_rear_castor_joint" type="continuous">
    <origin rpy="-1.5707963267948966 0 0" xyz="           -0.23            -0.16            -0.12990000000000002         "/>
    <parent link="base_link"/>
    <child link="right_rear_castor"/>
    <axis xyz="0.0 0.0 1.0"/>
  </joint>
  <link name="left_front_pole">
    <collision>
      <geometry>
        <cylinder length="0.05" radius="0.015"/>
      </geometry>
    </collision>
  </link>
  <joint name="left_front_pole_joint" type="fixed">
    <origin xyz="0.235 0.2 0.15"/>
    <parent link="base_link"/>
    <child link="left_front_pole"/>
  </joint>
  <link name="right_front_pole">
    <collision>
      <geometry>
        <cylinder length="0.05" radius="0.015"/>
      </geometry>
    </collision>
  </link>
  <joint name="right_front_pole_joint" type="fixed">
    <origin xyz="0.235 -0.2 0.15"/>
    <parent link="base_link"/>
    <child link="right_front_pole"/>
  </joint>
  <link name="left_rear_pole">
    <collision>
      <geometry>
        <cylinder length="0.05" radius="0.015"/>
      </geometry>
    </collision>
  </link>
  <joint name="left_rear_pole_joint" type="fixed">
    <origin xyz="-0.235 0.2 0.15"/>
    <parent link="base_link"/>
    <child link="left_rear_pole"/>
  </joint>
  <link name="right_rear_pole">
    <collision>
      <geometry>
        <cylinder length="0.05" radius="0.015"/>
      </geometry>
    </collision>
  </link>
  <joint name="right_rear_pole_joint" type="fixed">
    <origin xyz="-0.235 -0.2 0.15"/>
    <parent link="base_link"/>
    <child link="right_rear_pole"/>
  </joint>
  <link name="lidar_link">
    <visual>
      <geometry>
        <cylinder length="0.04" radius="0.035"/>
      </geometry>
    </visual>
  </link>
  <joint name="lidar_mount" type="fixed">
    <origin xyz="0.22 0.0 0.145"/>
    <parent link="base_link"/>
    <child link="lidar_link"/>
  </joint>
  <link name="camera_link">
    <visual>
      <origin rpy="0 0 0" xyz="0 0 0"/>
      <geometry>
        <box size="0.025 0.09 0.025"/>
      </geometry>
    </visual>
  </link>
  <link name="camera_optical"/>
  <joint name="camera_joint" type="fixed">
    <parent link="base_link"/>
    <child link="camera_link"/>
    <origin xyz="0.317 0 0.1"/>
  </joint>
  <joint name="camera_optical_mount" type="fixed">
    <parent link="camera_link"/>
    <child link="camera_optical"/>
    <origin rpy="-1.5707963267948966 0 -1.5707963267948966" xyz="0 0 0"/>
  </joint>
  <link name="imu_link"/>
  <joint name="imu_mount" type="fixed">
    <parent link="base_link"/>
    <child link="imu_link"/>
    <origin rpy="0 0 0" xyz="0 0 0"/>
  </joint>
  <gazebo reference="base_link">
    <material>Gazebo/White</material>
  </gazebo>
  <gazebo reference="left_wheel">
    <material>Gazebo/Black</material>
  </gazebo>
  <gazebo reference="right_wheel">
    <material>Gazebo/Black</material>
  </gazebo>
  <gazebo reference="left_front_castor">
    <material>Gazebo/Yellow</material>
  </gazebo>
  <gazebo reference="right_front_castor">
    <material>Gazebo/Yellow</material>
  </gazebo>
  <gazebo reference="left_rear_castor">
    <material>Gazebo/Yellow</material>
  </gazebo>
  <gazebo reference="right_rear_castor">
    <material>Gazebo/Yellow</material>
  </gazebo>
  <!-- imu -->
  <gazebo reference="imu_link">
    <gravity>true</gravity>
    <sensor name="imu_sensor" type="imu">
      <always_on>true</always_on>
      <update_rate>10</update_rate>
      <visualize>true</visualize>
      <topic>__default_topic__</topic>
      <plugin filename="libgazebo_ros_imu_sensor.so" name="imu_plugin">
        <ros>
          <remapping>~/out:=imu</remapping>
        </ros>
        <topicName>imu</topicName>
        <bodyName>imu_link</bodyName>
        <updateRateHZ>10.0</updateRateHZ>
        <gaussianNoise>0.05</gaussianNoise>
        <xyzOffset>0 0 0</xyzOffset>
        <rpyOffset>0 0 0</rpyOffset>
        <frame_name>imu_link</frame_name>
        <initialOrientationAsReference>false</initialOrientationAsReference>
      </plugin>
      <pose>0 0 0 0 0 0</pose>
    </sensor>
  </gazebo>
  <!-- lidar-->
  <gazebo reference="lidar_link">
    <sensor name="lidar_sensor" type="ray">
      <pose>0 0 0 0 0 0</pose>
      <visualize>true</visualize>
      <always_on>true</always_on>
      <update_rate>40</update_rate>
      <ray>
        <scan>
          <horizontal>
            <samples>720</samples>
            <resolution>1</resolution>
            <min_angle>-3.1415926</min_angle>
            <max_angle>3.1415926</max_angle>
          </horizontal>
        </scan>
        <range>
          <min>0.05</min>
          <max>16.0</max>
          <resolution>0.03</resolution>
        </range>
        <noise>
          <type>gaussian</type>
          <mean>0.0</mean>
          <stddev>0.03</stddev>
        </noise>
      </ray>
      <plugin filename="libgazebo_ros_ray_sensor.so" name="lidar_controller">
        <ros>
          <remapping>~/out:=scan</remapping>
        </ros>
        <output_type>sensor_msgs/LaserScan</output_type>
        <topicName>scan</topicName>
        <frame_name>lidar_link</frame_name>
      </plugin>
    </sensor>
  </gazebo>
  <gazebo reference="camera_link">
    <sensor name="camera" type="depth">
      <always_on>1</always_on>
      <update_rate>20.0</update_rate>
      <camera name="d435">
        <pose>0 0 0 0 0 3.14</pose>
        <horizontal_fov>1.3962634</horizontal_fov>
        <image>
          <width>1600</width>
          <height>900</height>
          <format>R8G8B8</format>
        </image>
        <clip>
          <near>0.005</near>
          <far>10.0</far>
        </clip>
      </camera>
      <plugin filename="libgazebo_ros_camera.so" name="camera_controller">
        <baseline>0.2</baseline>
        <alwaysOn>true</alwaysOn>
        <updateRate>1.0</updateRate>
        <cameraName>camera</cameraName>
        <imageTopicName>color/image_raw</imageTopicName>
        <cameraInfoTopicName>color/camera_info</cameraInfoTopicName>
        <frame_name>camera_link</frame_name>
        <hackBaseline>0.07</hackBaseline>
      </plugin>
    </sensor>
  </gazebo>
  <ros2_control name="GazeboSystem" type="system">
    <hardware>
      <plugin>gazebo_ros2_control/GazeboSystem</plugin>
    </hardware>
    <joint name="left_wheel_joint">
      <command_interface name="effort"/>
      <command_interface name="velocity"/>
      <state_interface name="velocity"/>
      <state_interface name="effort"/>
    </joint>
    <joint name="right_wheel_joint">
      <command_interface name="effort"/>
      <command_interface name="velocity"/>
      <state_interface name="velocity"/>
      <state_interface name="effort"/>
    </joint>
  </ros2_control>
  <gazebo>
    <plugin filename="libgazebo_ros2_control.so" name="gazebo_ros2_wheel_control">
      <parameters>/home/pi31415/xxx2_ws/install/xxx_gazebo/share/xxx_gazebo/config/ros2_controllers_config.yaml</parameters>
    </plugin>
  </gazebo>
</robot>
